Workbook

Sheet README
A1: Mongol Potential — Pricing & Unit Economics Model
B2: Built 14 Aug 2026 for the centre opening 1 Sept 2026. Currency: Mongolian tugrik (MNT, ₮) unless marked USD.
A4: WHAT THIS IS — AND WHAT IT IS NOT
B5: This model gives you the ARITHMETIC to choose a price. It deliberately does NOT recommend one.
B6: Every table shows a RANGE of price points and what each one implies for break-even, profit and risk. The choice is yours.
B8: Change the numbers on the ASSUMPTIONS sheet. Everything else recalculates. Do not type over formulas (black text).
B9: • BLUE text = an input you can edit
B10: • YELLOW fill = a key assumption most worth stress-testing
B11: • BLACK text = a formula, do not overwrite
B12: • GREEN text = a link to another sheet
A14: SHEET GUIDE
B15: Assumptions | C15: Every editable input. Start here.
B16: Benchmarks | C16: Real Ulaanbaatar market prices found, with sources and dates. Also lists what could NOT be verified.
B17: Capacity | C17: Rooms → sessions per week → realistic student capacity. Utilisation, not theoretical maximum.
B18: Costs | C18: Monthly cost base. Includes owner-taught vs all-hired staffing comparison.
B19: PriceGrid | C19: The core output: break-even student count and profit at each price point × cohort size.
B20: PnL | C20: Full monthly and annual P&L at the price you select on Assumptions.
B21: Enrolment | C21: Full-school-year enrolment vs monthly subscription, including the cost of churn.
B22: Website | C22: Bundled into the centre fee vs sold as an add-on. Then public (non-centre) website pricing.
B23: CashFlow | C23: Month-by-month Aug 2026 → Aug 2027 against the school year. Tight months flagged.
B24: Scenarios | C24: Conservative / Base / Stretch side by side.
A26: THREE THINGS TO KNOW BEFORE YOU READ THE NUMBERS
B27: 1. MISSING SOURCE DOCUMENTS. The brief asked me to read /docs/plan/03-ROADMAP.md and /docs/plan/05-INTEGRITY-AND-MOTIVATION.md.
B28: Neither file exists in this repository or anywhere on this machine (the repo has only docs/superpowers/). I have NOT guessed at their
B29: contents. The premium-justification logic on the Website sheet is built from the mechanism described in the brief itself
B30: (verified in-room attempts → trustworthy predicted ЭЕШ score → monthly parent report). Re-check that section against doc 05.
B32: 2. THE OWNER'S TEACHING TIME IS COSTED, not free. See Assumptions rows 'Owner teaching'. If you zero it out the model will
B33: flatter itself and mislead the pricing decision. Keep it costed even while you are not paying yourself.
B35: 3. MARKET DATA IS THIN AND PARTLY UNVERIFIABLE. Mongolian tutoring centres mostly publish prices on Facebook, not on indexable
B36: websites, and several .mn domains could not be opened from this machine. Benchmarks marked LOW confidence are search-snippet
B37: level only. Before you commit to a price, phone three competitors and replace those cells with what they actually quote.

Sheet Assumptions
A1: Assumptions — edit these
B2: Blue = editable input. Yellow = key lever. Everything on other sheets flows from here.
A4: GENERAL
B5: Exchange rate (MNT per USD) | C5: 3599 | D5: ₮/$ | E5: xe.com, 13 Aug 2026: 1 USD = 3,599.11 MNT
B6: Billing months per school year | C6: 10 | D6: months | E6: Sept–June. Change if you bill 9 or 12.
B7: Weeks per month (teaching) | C7: 4.33 | D7: weeks | E7: 52/12
A8: CAPACITY — rooms and sessions
B9: Room A (living room) — max students | C9: 20 | D9: students | E9: Brief: '~20 students per 2-hour session'. Treated as the main teaching room.
B10: Room B (small bedroom) — max students | C10: 8 | D10: students | E10: ASSUMPTION — not stated in brief. Set to 0 to model one room only.
B11: Use Room B in parallel? (1 = yes, 0 = no) | C11: 1 | D11: 1/0 | E11: Parallel sessions need a second teacher at the same time.
B12: Centre-wide concurrent cap (fire/comfort) | C12: 20 | D12: students | E12: Warning fires on Capacity sheet if cohorts exceed this.
B13: Session length | C13: 2 | D13: hours | E13: Brief.
B14: Weekday after-school slots per day per room | C14: 2 | D14: slots | E14: e.g. 16:00–18:00 and 18:00–20:00.
B15: Weekdays used | C15: 5 | D15: days
B16: Weekend slots per day per room | C16: 4 | D16: slots | E16: e.g. 10:00–18:00.
B17: Weekend days used | C17: 2 | D17: days
B18: Realistic slot utilisation | C18: 0.55 | D18: % | E18: NOT theoretical max. Demand concentrates in the evening peak; some slots will never fill.
B19: Sessions per student per week | C19: 2 | D19: sessions | E19: Benchmark: Eduzone ЭЕШ maths runs 2×/week.
A20: ENROLMENT
B21: Cohort size — selected scenario | C21: 16 | D21: students | E21: PriceGrid also shows 12 / 16 / 20 side by side.
B22: Cohort size — Room B small group | C22: 6 | D22: students | E22: ASSUMPTION.
B23: Seat fill rate | C23: 0.85 | D23: % | E23: Share of available seats actually sold.
B24: Share enrolling for the full school year | C24: 0.6 | D24: % | E24: Owner prefers full-year; monthly accepted. ASSUMPTION.
B25: Monthly churn — monthly-plan students | C25: 0.05 | D25: %/mo | E25: ASSUMPTION. Stress-test this: it drives the year-vs-monthly answer.
A26: PRICE (the decision — model shows a range, this is just the selected point)
B27: Tuition per student per month | C27: 450000 | D27: ₮/mo | E27: SELECTED SCENARIO ONLY. See PriceGrid for the full range 200k–900k.
B28: Discount for paying full year upfront | C28: 0.1 | D28: % | E28: ASSUMPTION.
B29: One-off registration / materials fee | C29: 0 | D29: ₮ | E29: Set to 0 if not charged.
A30: STAFF COSTS — owner time IS costed (see README point 2)
B31: Hired teacher — monthly gross salary | C31: 3500000 | D31: ₮/mo | E31: Mongolian teacher BASIC salary rose to 2.8m₮/mo Jan 2026 (+50%), +26% more due 1 Nov 2026, union target 3.5m₮ (Education International). A strong private-centre maths teacher costs a premium over basic.
B32: Hired teacher — contact hours capacity per week | C32: 20 | D32: hrs/wk | E32: Teaching hours only; excludes prep/marking.
B33: Employer social insurance | C33: 0.145 | D33: % | E33: Mongolia employer contribution 12.5%–14.5%; TradingEconomics shows 14.5% company rate.
B34: Owner teaching hours per week | C34: 12 | D34: hrs/wk | E34: Contact hours the owner personally teaches.
B35: Owner teaching — cost per hour (opportunity cost) | C35: 50000 | D35: ₮/hr | E35: MUST NOT be zero. Proxy: private lessons in UB advertise from ₮50,000/hr (TUTOROO) — that listing is LANGUAGE tutoring, so treat as a floor, not a maths rate.
B36: Admin / front desk — monthly gross | C36: 1200000 | D36: ₮/mo | E36: ASSUMPTION. Set headcount to 0 if the owner does admin (then raise owner hours).
B37: Admin headcount | C37: 1 | D37: FTE
A38: FACILITY
B39: Rent, or imputed market rent if owned | C39: 2000000 | D39: ₮/mo | E39: Cost it even if you own it. UB 2-room average rent ₮1.85m/mo (ikon.mn, Feb 2026); Sukhbaatar district 1.40–4.61m. A ground-floor unit fit for a centre likely sits at/above the top of the 2-room range.
B40: Utilities (heating, power, water) | C40: 400000 | D40: ₮/mo | E40: UNVERIFIED — no source found. Replace with your actual bill.
B41: Internet | C41: 60000 | D41: ₮/mo | E41: UNVERIFIED — replace with actual.
...

Sheet Benchmarks
A1: Ulaanbaatar market benchmarks
B2: Everything below was found by web search on 14 Aug 2026. Confidence is graded honestly. LOW = search-snippet only, primary page could not be opened from this machine (many .mn domains were blocked). Verify by phone before pricing.
B4: What | C4: Price | D4: Basis | E4: Confidence | F4: Source / date
B5: GROUP ЭЕШ PREP — the market you are pricing against
B6: Eduzone сургалтын төв — maths ЭЕШ prep | C6: 1,800,000 ₮ / year | D6: 2 sessions/week, group | E6: MEDIUM | F6: unread.today course listing, via search 14 Aug 2026
B7: Eduzone — physics / English | C7: 1,600,000 ₮ / year | D7: 2 sessions/week, group | E7: MEDIUM | F7: same listing
B8: iMath.mn — summer programme | C8: 360,000 ₮ | D8: daily 15:00–17:00, summer block | E8: LOW | F8: search snippet 14 Aug 2026; imath.mn blocked from this machine
B9: Оюунлаг school — бэлтгэл анги (prep class) | C9: 900,000 ₮ | D9: prep class, period not stated | E9: LOW | F9: shuurhai.mn private-school roundup, via search
B11: PRIVATE 1-ON-1 TUTORING
B12: UB private lessons (TUTOROO listings) | C12: from 50,000 ₮ / hour | D12: 1-on-1, in person/online | E12: LOW — WRONG SUBJECT | F12: tutoroo.co, Mongolian- and English-language tutors. NOT maths. Use as a floor only.
B13: Online Mongolian-language lessons | C13: $10–30 / hour (avg $18) | D13: 1-on-1 online | E13: LOW — WRONG SUBJECT | F13: AmazingTalker / Superprof. Language, not maths.
B15: SAT PREP
B16: SAT prep course price in Mongolia | C16: NOT FOUND | D16: — | E16: GAP | F16: No published price located. Thin market, as expected. Phone EA MUST / GAPE / Absolute.
B17: IELTS exam fee (adjacent test-prep anchor) | C17: 839,000 ₮ | D17: exam sitting, not tuition | E17: MEDIUM | F17: ikon.mn 2025 IELTS schedule
B19: TOP OF MARKET — what UB parents already pay for perceived quality
B20: Private secondary schools — average | C20: 8,000,000–10,000,000 ₮ / year | D20: full school | E20: MEDIUM | F20: eagle.mn
B21: Private secondary schools — full range | C21: 1,700,000–59,000,000 ₮ / year | D21: full school | E21: MEDIUM | F21: ikon.mn
B22: Оюунлаг school | C22: 8,512,000 ₮ / year | D22: full school | E22: MEDIUM | F22: shuurhai.mn roundup
B23: Улаанбаатар Элит school | C23: 9,950,000 ₮ / year | D23: full school | E23: MEDIUM | F23: shuurhai.mn roundup
B24: International School of Ulaanbaatar | C24: $24,190–$44,060 / year | D24: full school, no employer aid | E24: HIGH | F24: ISU published tuition-fees PDF, 2025/26
B26: COST INPUTS
B27: Teacher basic salary — from Jan 2026 | C27: 2,800,000 ₮ / month | D27: state basic, +50% | E27: HIGH | F27: Education International, Dec 2025 settlement
B28: Further rise due 1 Nov 2026 | C28: +26% | D28: on basic | E28: HIGH | F28: Education International
B29: Union target | C29: 3,500,000 ₮ / month | D29: on basic | E29: HIGH | F29: Education International / FMESU
B30: Employer social insurance | C30: 12.5%–14.5% | D30: on gross payroll | E30: HIGH | F30: PwC / TradingEconomics (14.5% company rate)
B31: UB 2-room apartment rent — average | C31: 1,850,000 ₮ / month | D31: residential | E31: MEDIUM | F31: ikon.mn, Feb 2026
B32: UB 2-room rent — Sukhbaatar district | C32: 1,400,000–4,610,000 ₮ / month | D32: residential | E32: MEDIUM | F32: ikon.mn
B33: Exchange rate | C33: 1 USD = 3,599.11 ₮ | D33: spot | E33: HIGH | F33: xe.com, 13 Aug 2026
A35: WHAT I COULD NOT FIND — do not let these gaps get filled with guesses
B36: • A published per-hour rate for private MATHS tutoring in Ulaanbaatar. The ₮50,000/hr figure is language tutoring on an expat-facing platform.
B37: • Any SAT preparation course price in Mongolia.
B38: • Monthly (as opposed to annual) fees for ЭЕШ centres — most advertise a year price or quote by phone.
B39: • Utilities and heating cost for a converted ground-floor apartment.
B40: • Competitor cohort sizes, which is what actually determines their margin and therefore how much room you have above them.
B42: Most Mongolian centres price on Facebook and Instagram, not on indexable websites, and several .mn domains were blocked from this machine.
B43: The fastest fix is three phone calls. Ask: price, sessions per week, group size, and whether that price is per month or per year.

Sheet Capacity
A1: Capacity — realistic, not theoretical
B2: A 'slot' is one 2-hour session in one room. A cohort meets 'sessions per week' times, so each cohort consumes that many slots.
A4: SLOTS PER WEEK, PER ROOM
B5: Theoretical slots per week per room | C5: =(Assumptions!$C$14*Assumptions!$C$15)+(Assumptions!$C$16*Assumptions!$C$17) | E5: Every slot the timetable could physically hold.
B6: Realistic slots per week per room (after utilisation) | C6: =C5*Assumptions!$C$18 | E6: This is the number the model uses. The evening peak fills; mid-afternoon largely does not.
B7: Realistic slots per week — whole centre | C7: =C6*(1+Assumptions!$C$11) | E7: Room A, plus Room B if in use.
A9: COHORTS AND STUDENTS
B10: Cohorts that fit in Room A | C10: =C6/Assumptions!$C$19 | E10: Each cohort uses 'sessions per week' slots.
B11: Cohorts that fit in Room B | C11: =C6/Assumptions!$C$19*Assumptions!$C$11
B12: Students — Room A | C12: =C10*MIN(Assumptions!$C$21,Assumptions!$C$9)*Assumptions!$C$23 | E12: Cohort size is capped by the room's physical capacity.
B13: Students — Room B | C13: =C11*MIN(Assumptions!$C$22,Assumptions!$C$10)*Assumptions!$C$23
B14: TOTAL STUDENTS AT STEADY STATE | C14: =ROUND(C12+C13,0) | E14: The enrolled roll the centre can actually serve on these assumptions.
A16: TEACHING LOAD
B17: Contact hours per week (all cohorts) | C17: =C7*Assumptions!$C$13
B18: …covered by the owner | C18: =MIN(Assumptions!$C$34,C17)
B19: …left for hired teachers | C19: =MAX(0,C17-C18)
B20: Hired teachers required | C20: =ROUNDUP(C19/Assumptions!$C$32,0) | E20: Rounded up — you cannot hire a fraction of a teacher.
A22: CHECKS
B23: Students in the building during a parallel session | C23: =MIN(Assumptions!$C$21,Assumptions!$C$9)+MIN(Assumptions!$C$22,Assumptions!$C$10)*Assumptions!$C$11
B24: Within the centre-wide concurrent cap? | C24: =IF(C23<=Assumptions!$C$12,"OK","OVER CAP — reduce cohort size or stop using Room B in parallel")
B25: Second teacher needed at the same time? | C25: =IF(Assumptions!$C$11=1,"YES — parallel sessions need 2 adults in the building","No")
B27: If 'OVER CAP' appears: either the cohort is too big for the flat, or Room B should run at a different time rather than in parallel. Running Room B in parallel is what forces a second salaried teacher — check on the Costs sheet what that costs you.
B29: IMPORTANT — this is the STEADY-STATE roll, not what you will have in September. It is the number of enrolled students the timetable can serve once the centre is full. The CashFlow sheet ramps up to it. A new centre does not open full.
B31: Physical ceiling on the roll (100% fill, for reference) | C31: =(C6*Assumptions!$C$9+C6*Assumptions!$C$10*Assumptions!$C$11)/Assumptions!$C$19 | E31: Every seat in every realistic slot, sold. The roll above should sit comfortably below this.

Sheet Costs
A1: Monthly cost base
B2: Fixed costs do not move with student numbers. Variable costs do. The split is what sets the break-even.
A4: FIXED COSTS PER MONTH
B5: Hired teachers (incl. employer social insurance) | C5: =Capacity!$C$20*Assumptions!$C$31*(1+Assumptions!$C$33) | E5: Headcount from Capacity sheet.
B6: Owner teaching time (opportunity cost — NOT free) | C6: =Capacity!$C$18*Assumptions!$C$7*Assumptions!$C$35 | E6: Costed even though unpaid today. Removing this would flatter the model and mislead the price decision.
B7: Admin / front desk (incl. social insurance) | C7: =Assumptions!$C$37*Assumptions!$C$36*(1+Assumptions!$C$33)
B8: Rent (or imputed rent if owned) | C8: =Assumptions!$C$39
B9: Utilities + internet | C9: =Assumptions!$C$40+Assumptions!$C$41 | E9: UNVERIFIED inputs.
B10: Technology (Supabase, hosting, domain) | C10: =(Assumptions!$C$46+Assumptions!$C$47)*Assumptions!$C$5 | E10: Converted at the rate on Assumptions.
B11: Marketing | C11: =Assumptions!$C$48
B12: Other / contingency | C12: =Assumptions!$C$49
B13: TOTAL FIXED COST PER MONTH | C13: =SUM(C5:C12)
A15: VARIABLE COST PER STUDENT PER MONTH
B16: Materials & printing | C16: =Assumptions!$C$43
B17: Food & coffee | C17: =Assumptions!$C$44 | E17: Set to 0 on Assumptions to test dropping it.
B18: TOTAL VARIABLE COST PER STUDENT | C18: =C16+C17
A20: STAFFING MODEL — owner-taught vs all-hired
B21: Same teaching load, two ways to cover it. The difference is what the owner's time is worth.
B23: Model A — owner teaches (current assumption)
B24: Hired teacher cost | C24: =C5
B25: Owner time costed | C25: =C6
B26: Total teaching cost | C26: =C24+C25
B28: Model B — all teaching hired, owner teaches nothing
B29: Hired teachers required | C29: =ROUNDUP(Capacity!$C$17/Assumptions!$C$32,0)
B30: Hired teacher cost | C30: =C29*Assumptions!$C$31*(1+Assumptions!$C$33)
B31: Total teaching cost | C31: =C30
B33: Cash saved per month by the owner teaching | C33: =C31-C24 | E33: Real cash difference. Compare against the owner's costed time directly below — if the owner's time is worth more than this, hiring is the better trade.
B34: …versus the value of the owner's time | C34: =C6
B35: Owner teaching is economically worth it? | C35: =IF(C33>=C6,"YES — saves more cash than the time is worth","NO — the owner's time is worth more than the saving")
B37: This comparison is only as honest as the owner hourly rate on Assumptions. If that rate is set too low, owner-teaching will always look free and the centre will look more profitable than it is.

Sheet PriceGrid
A1: Price grid — the core output
B2: No price is recommended. Read across: what each price implies for break-even and profit, at three cohort sizes. Break-even does NOT change with cohort size (the same rooms, teachers and rent) — cohort size determines whether you can REACH it.
B4: Seats available at each cohort size (steady state): | F4: =ROUND(Capacity!$C$10*MIN(12,Assumptions!$C$9)*Assumptions!$C$23+Capacity!$C$11*MIN(Assumptions!$C$22,Assumptions!$C$10)*Assumptions!$C$23,0) | G4: =ROUND(Capacity!$C$10*MIN(16,Assumptions!$C$9)*Assumptions!$C$23+Capacity!$C$11*MIN(Assumptions!$C$22,Assumptions!$C$10)*Assumptions!$C$23,0) | H4: =ROUND(Capacity!$C$10*MIN(20,Assumptions!$C$9)*Assumptions!$C$23+Capacity!$C$11*MIN(Assumptions!$C$22,Assumptions!$C$10)*Assumptions!$C$23,0)
B5: Compare these against the break-even column: if break-even exceeds the seats available, that price cannot work at this capacity.
B7: Tuition ₮/student/month | C7: Annual ₮/student | D7: vs Eduzone ЭЕШ (1.8m₮/yr) | E7: Break-even students | F7: Profit/month cohort 12 | G7: Profit/month cohort 16 | H7: Profit/month cohort 20 | I7: Profit/year cohort 16 | J7: Margin cohort 16
B8: 200000 | C8: =B8*Assumptions!$C$6 | D8: =C8/1800000 | E8: =IFERROR(Costs!$C$13/((B8*(1-Assumptions!$C$24*Assumptions!$C$28))-Costs!$C$18),"n/a") | F8: =(Capacity!$C$10*MIN(12,Assumptions!$C$9)*Assumptions!$C$23+Capacity!$C$11*MIN(Assumptions!$C$22,Assumptions!$C$10)*Assumptions!$C$23)*((B8*(1-Assumptions!$C$24*Assumptions!$C$28))-Costs!$C$18)-Costs!$C$13 | G8: =(Capacity!$C$10*MIN(16,Assumptions!$C$9)*Assumptions!$C$23+Capacity!$C$11*MIN(Assumptions!$C$22,Assumptions!$C$10)*Assumptions!$C$23)*((B8*(1-Assumptions!$C$24*Assumptions!$C$28))-Costs!$C$18)-Costs!$C$13 | H8: =(Capacity!$C$10*MIN(20,Assumptions!$C$9)*Assumptions!$C$23+Capacity!$C$11*MIN(Assumptions!$C$22,Assumptions!$C$10)*Assumptions!$C$23)*((B8*(1-Assumptions!$C$24*Assumptions!$C$28))-Costs!$C$18)-Costs!$C$13 | I8: =G8*Assumptions!$C$6 | J8: =IFERROR(G8/((Capacity!$C$10*MIN(16,Assumptions!$C$9)*Assumptions!$C$23+Capacity!$C$11*MIN(Assumptions!$C$22,Assumptions!$C$10)*Assumptions!$C$23)*(B8*(1-Assumptions!$C$24*Assumptions!$C$28))),"n/a")
B9: 250000 | C9: =B9*Assumptions!$C$6 | D9: =C9/1800000 | E9: =IFERROR(Costs!$C$13/((B9*(1-Assumptions!$C$24*Assumptions!$C$28))-Costs!$C$18),"n/a") | F9: =(Capacity!$C$10*MIN(12,Assumptions!$C$9)*Assumptions!$C$23+Capacity!$C$11*MIN(Assumptions!$C$22,Assumptions!$C$10)*Assumptions!$C$23)*((B9*(1-Assumptions!$C$24*Assumptions!$C$28))-Costs!$C$18)-Costs!$C$13 | G9: =(Capacity!$C$10*MIN(16,Assumptions!$C$9)*Assumptions!$C$23+Capacity!$C$11*MIN(Assumptions!$C$22,Assumptions!$C$10)*Assumptions!$C$23)*((B9*(1-Assumptions!$C$24*Assumptions!$C$28))-Costs!$C$18)-Costs!$C$13 | H9: =(Capacity!$C$10*MIN(20,Assumptions!$C$9)*Assumptions!$C$23+Capacity!$C$11*MIN(Assumptions!$C$22,Assumptions!$C$10)*Assumptions!$C$23)*((B9*(1-Assumptions!$C$24*Assumptions!$C$28))-Costs!$C$18)-Costs!$C$13 | I9: =G9*Assumptions!$C$6 | J9: =IFERROR(G9/((Capacity!$C$10*MIN(16,Assumptions!$C$9)*Assumptions!$C$23+Capacity!$C$11*MIN(Assumptions!$C$22,Assumptions!$C$10)*Assumptions!$C$23)*(B9*(1-Assumptions!$C$24*Assumptions!$C$28))),"n/a")
B10: 300000 | C10: =B10*Assumptions!$C$6 | D10: =C10/1800000 | E10: =IFERROR(Costs!$C$13/((B10*(1-Assumptions!$C$24*Assumptions!$C$28))-Costs!$C$18),"n/a") | F10: =(Capacity!$C$10*MIN(12,Assumptions!$C$9)*Assumptions!$C$23+Capacity!$C$11*MIN(Assumptions!$C$22,Assumptions!$C$10)*Assumptions!$C$23)*((B10*(1-Assumptions!$C$24*Assumptions!$C$28))-Costs!$C$18)-Costs!$C$13 | G10: =(Capacity!$C$10*MIN(16,Assumptions!$C$9)*Assumptions!$C$23+Capacity!$C$11*MIN(Assumptions!$C$22,Assumptions!$C$10)*Assumptions!$C$23)*((B10*(1-Assumptions!$C$24*Assumptions!$C$28))-Costs!$C$18)-Costs!$C$13 | H10: =(Capacity!$C$10*MIN(20,Assumptions!$C$9)*Assumptions!$C$23+Capacity!$C$11*MIN(Assumptions!$C$22,Assumptions!$C$10)*Assumptions!$C$23)*((B10*(1-Assumptions!$C$24*Assumptions!$C$28))-Costs!$C$18)-Costs!$C$13 | I10: =G10*Assumptions!$C$6 | J10: =IFERROR(G10/((Capacity!$C$10*MIN(16,Assumptions!$C$9)*Assumptions!$C$23+Capacity!$C$11*MIN(Assumptions!$C$22,Assumptions!$C$10)*Assumptions!$C$23)*(B10*(1-Assumptions!$C$24*Assumptions!$C$28))),"n/a")
B11: 350000 | C11: =B11*Assumptions!$C$6 | D11: =C11/1800000 | E11: =IFERROR(Costs!$C$13/((B11*(1-Assumptions!$C$24*Assumptions!$C$28))-Costs!$C$18),"n/a") | F11: =(Capacity!$C$10*MIN(12,Assumptions!$C$9)*Assumptions!$C$23+Capacity!$C$11*MIN(Assumptions!$C$22,Assumptions!$C$10)*Assumptions!$C$23)*((B11*(1-Assumptions!$C$24*Assumptions!$C$28))-Costs!$C$18)-Costs!$C$13 | G11: =(Capacity!$C$10*MIN(16,Assumptions!$C$9)*Assumptions!$C$23+Capacity!$C$11*MIN(Assumptions!$C$22,Assumptions!$C$10)*Assumptions!$C$23)*((B11*(1-Assumptions!$C$24*Assumptions!$C$28))-Costs!$C$18)-Costs!$C$13 | H11: =(Capacity!$C$10*MIN(20,Assumptions!$C$9)*Assumptions!$C$23+Capacity!$C$11*MIN(Assumptions!$C$22,Assumptions!$C$10)*Assumptions!$C$23)*((B11*(1-Assumptions!$C$24*Assumptions!$C$28))-Costs!$C$18)-Costs!$C$13 | I11: =G11*Assumptions!$C$6 | J11: =IFERROR(G11/((Capacity!$C$10*MIN(16,Assumptions!$C$9)*Assumptions!$C$23+Capacity!$C$11*MIN(Assumptions!$C$22,Assumptions!$C$10)*Assumptions!$C$23)*(B11*(1-Assumptions!$C$24*Assumptions!$C$28))),"n/a")
B12: 400000 | C12: =B12*Assumptions!$C$6 | D12: =C12/1800000 | E12: =IFERROR(Costs!$C$13/((B12*(1-Assumptions!$C$24*Assumptions!$C$28))-Costs!$C$18),"n/a") | F12: =(Capacity!$C$10*MIN(12,Assumptions!$C$9)*Assumptions!$C$23+Capacity!$C$11*MIN(Assumptions!$C$22,Assumptions!$C$10)*Assumptions!$C$23)*((B12*(1-Assumptions!$C$24*Assumptions!$C$28))-Costs!$C$18)-Costs!$C$13 | G12: =(Capacity!$C$10*MIN(16,Assumptions!$C$9)*Assumptions!$C$23+Capacity!$C$11*MIN(Assumptions!$C$22,Assumptions!$C$10)*Assumptions!$C$23)*((B12*(1-Assumptions!$C$24*Assumptions!$C$28))-Costs!$C$18)-Costs!$C$13 | H12: =(Capacity!$C$10*MIN(20,Assumptions!$C$9)*Assumptions!$C$23+Capacity!$C$11*MIN(Assumptions!$C$22,Assumptions!$C$10)*Assumptions!$C$23)*((B12*(1-Assumptions!$C$24*Assumptions!$C$28))-Costs!$C$18)-Costs!$C$13 | I12: =G12*Assumptions!$C$6 | J12: =IFERROR(G12/((Capacity!$C$10*MIN(16,Assumptions!$C$9)*Assumptions!$C$23+Capacity!$C$11*MIN(Assumptions!$C$22,Assumptions!$C$10)*Assumptions!$C$23)*(B12*(1-Assumptions!$C$24*Assumptions!$C$28))),"n/a")
B13: 450000 | C13: =B13*Assumptions!$C$6 | D13: =C13/1800000 | E13: =IFERROR(Costs!$C$13/((B13*(1-Assumptions!$C$24*Assumptions!$C$28))-Costs!$C$18),"n/a") | F13: =(Capacity!$C$10*MIN(12,Assumptions!$C$9)*Assumptions!$C$23+Capacity!$C$11*MIN(Assumptions!$C$22,Assumptions!$C$10)*Assumptions!$C$23)*((B13*(1-Assumptions!$C$24*Assumptions!$C$28))-Costs!$C$18)-Costs!$C$13 | G13: =(Capacity!$C$10*MIN(16,Assumptions!$C$9)*Assumptions!$C$23+Capacity!$C$11*MIN(Assumptions!$C$22,Assumptions!$C$10)*Assumptions!$C$23)*((B13*(1-Assumptions!$C$24*Assumptions!$C$28))-Costs!$C$18)-Costs!$C$13 | H13: =(Capacity!$C$10*MIN(20,Assumptions!$C$9)*Assumptions!$C$23+Capacity!$C$11*MIN(Assumptions!$C$22,Assumptions!$C$10)*Assumptions!$C$23)*((B13*(1-Assumptions!$C$24*Assumptions!$C$28))-Costs!$C$18)-Costs!$C$13 | I13: =G13*Assumptions!$C$6 | J13: =IFERROR(G13/((Capacity!$C$10*MIN(16,Assumptions!$C$9)*Assumptions!$C$23+Capacity!$C$11*MIN(Assumptions!$C$22,Assumptions!$C$10)*Assumptions!$C$23)*(B13*(1-Assumptions!$C$24*Assumptions!$C$28))),"n/a")
B14: 500000 | C14: =B14*Assumptions!$C$6 | D14: =C14/1800000 | E14: =IFERROR(Costs!$C$13/((B14*(1-Assumptions!$C$24*Assumptions!$C$28))-Costs!$C$18),"n/a") | F14: =(Capacity!$C$10*MIN(12,Assumptions!$C$9)*Assumptions!$C$23+Capacity!$C$11*MIN(Assumptions!$C$22,Assumptions!$C$10)*Assumptions!$C$23)*((B14*(1-Assumptions!$C$24*Assumptions!$C$28))-Costs!$C$18)-Costs!$C$13 | G14: =(Capacity!$C$10*MIN(16,Assumptions!$C$9)*Assumptions!$C$23+Capacity!$C$11*MIN(Assumptions!$C$22,Assumptions!$C$10)*Assumptions!$C$23)*((B14*(1-Assumptions!$C$24*Assumptions!$C$28))-Costs!$C$18)-Costs!$C$13 | H14: =(Capacity!$C$10*MIN(20,Assumptions!$C$9)*Assumptions!$C$23+Capacity!$C$11*MIN(Assumptions!$C$22,Assumptions!$C$10)*Assumptions!$C$23)*((B14*(1-Assumptions!$C$24*Assumptions!$C$28))-Costs!$C$18)-Costs!$C$13 | I14: =G14*Assumptions!$C$6 | J14: =IFERROR(G14/((Capacity!$C$10*MIN(16,Assumptions!$C$9)*Assumptions!$C$23+Capacity!$C$11*MIN(Assumptions!$C$22,Assumptions!$C$10)*Assumptions!$C$23)*(B14*(1-Assumptions!$C$24*Assumptions!$C$28))),"n/a")
B15: 550000 | C15: =B15*Assumptions!$C$6 | D15: =C15/1800000 | E15: =IFERROR(Costs!$C$13/((B15*(1-Assumptions!$C$24*Assumptions!$C$28))-Costs!$C$18),"n/a") | F15: =(Capacity!$C$10*MIN(12,Assumptions!$C$9)*Assumptions!$C$23+Capacity!$C$11*MIN(Assumptions!$C$22,Assumptions!$C$10)*Assumptions!$C$23)*((B15*(1-Assumptions!$C$24*Assumptions!$C$28))-Costs!$C$18)-Costs!$C$13 | G15: =(Capacity!$C$10*MIN(16,Assumptions!$C$9)*Assumptions!$C$23+Capacity!$C$11*MIN(Assumptions!$C$22,Assumptions!$C$10)*Assumptions!$C$23)*((B15*(1-Assumptions!$C$24*Assumptions!$C$28))-Costs!$C$18)-Costs!$C$13 | H15: =(Capacity!$C$10*MIN(20,Assumptions!$C$9)*Assumptions!$C$23+Capacity!$C$11*MIN(Assumptions!$C$22,Assumptions!$C$10)*Assumptions!$C$23)*((B15*(1-Assumptions!$C$24*Assumptions!$C$28))-Costs!$C$18)-Costs!$C$13 | I15: =G15*Assumptions!$C$6 | J15: =IFERROR(G15/((Capacity!$C$10*MIN(16,Assumptions!$C$9)*Assumptions!$C$23+Capacity!$C$11*MIN(Assumptions!$C$22,Assumptions!$C$10)*Assumptions!$C$23)*(B15*(1-Assumptions!$C$24*Assumptions!$C$28))),"n/a")
B16: 600000 | C16: =B16*Assumptions!$C$6 | D16: =C16/1800000 | E16: =IFERROR(Costs!$C$13/((B16*(1-Assumptions!$C$24*Assumptions!$C$28))-Costs!$C$18),"n/a") | F16: =(Capacity!$C$10*MIN(12,Assumptions!$C$9)*Assumptions!$C$23+Capacity!$C$11*MIN(Assumptions!$C$22,Assumptions!$C$10)*Assumptions!$C$23)*((B16*(1-Assumptions!$C$24*Assumptions!$C$28))-Costs!$C$18)-Costs!$C$13 | G16: =(Capacity!$C$10*MIN(16,Assumptions!$C$9)*Assumptions!$C$23+Capacity!$C$11*MIN(Assumptions!$C$22,Assumptions!$C$10)*Assumptions!$C$23)*((B16*(1-Assumptions!$C$24*Assumptions!$C$28))-Costs!$C$18)-Costs!$C$13 | H16: =(Capacity!$C$10*MIN(20,Assumptions!$C$9)*Assumptions!$C$23+Capacity!$C$11*MIN(Assumptions!$C$22,Assumptions!$C$10)*Assumptions!$C$23)*((B16*(1-Assumptions!$C$24*Assumptions!$C$28))-Costs!$C$18)-Costs!$C$13 | I16: =G16*Assumptions!$C$6 | J16: =IFERROR(G16/((Capacity!$C$10*MIN(16,Assumptions!$C$9)*Assumptions!$C$23+Capacity!$C$11*MIN(Assumptions!$C$22,Assumptions!$C$10)*Assumptions!$C$23)*(B16*(1-Assumptions!$C$24*Assumptions!$C$28))),"n/a")
B17: 650000 | C17: =B17*Assumptions!$C$6 | D17: =C17/1800000 | E17: =IFERROR(Costs!$C$13/((B17*(1-Assumptions!$C$24*Assumptions!$C$28))-Costs!$C$18),"n/a") | F17: =(Capacity!$C$10*MIN(12,Assumptions!$C$9)*Assumptions!$C$23+Capacity!$C$11*MIN(Assumptions!$C$22,Assumptions!$C$10)*Assumptions!$C$23)*((B17*(1-Assumptions!$C$24*Assumptions!$C$28))-Costs!$C$18)-Costs!$C$13 | G17: =(Capacity!$C$10*MIN(16,Assumptions!$C$9)*Assumptions!$C$23+Capacity!$C$11*MIN(Assumptions!$C$22,Assumptions!$C$10)*Assumptions!$C$23)*((B17*(1-Assumptions!$C$24*Assumptions!$C$28))-Costs!$C$18)-Costs!$C$13 | H17: =(Capacity!$C$10*MIN(20,Assumptions!$C$9)*Assumptions!$C$23+Capacity!$C$11*MIN(Assumptions!$C$22,Assumptions!$C$10)*Assumptions!$C$23)*((B17*(1-Assumptions!$C$24*Assumptions!$C$28))-Costs!$C$18)-Costs!$C$13 | I17: =G17*Assumptions!$C$6 | J17: =IFERROR(G17/((Capacity!$C$10*MIN(16,Assumptions!$C$9)*Assumptions!$C$23+Capacity!$C$11*MIN(Assumptions!$C$22,Assumptions!$C$10)*Assumptions!$C$23)*(B17*(1-Assumptions!$C$24*Assumptions!$C$28))),"n/a")
B18: 700000 | C18: =B18*Assumptions!$C$6 | D18: =C18/1800000 | E18: =IFERROR(Costs!$C$13/((B18*(1-Assumptions!$C$24*Assumptions!$C$28))-Costs!$C$18),"n/a") | F18: =(Capacity!$C$10*MIN(12,Assumptions!$C$9)*Assumptions!$C$23+Capacity!$C$11*MIN(Assumptions!$C$22,Assumptions!$C$10)*Assumptions!$C$23)*((B18*(1-Assumptions!$C$24*Assumptions!$C$28))-Costs!$C$18)-Costs!$C$13 | G18: =(Capacity!$C$10*MIN(16,Assumptions!$C$9)*Assumptions!$C$23+Capacity!$C$11*MIN(Assumptions!$C$22,Assumptions!$C$10)*Assumptions!$C$23)*((B18*(1-Assumptions!$C$24*Assumptions!$C$28))-Costs!$C$18)-Costs!$C$13 | H18: =(Capacity!$C$10*MIN(20,Assumptions!$C$9)*Assumptions!$C$23+Capacity!$C$11*MIN(Assumptions!$C$22,Assumptions!$C$10)*Assumptions!$C$23)*((B18*(1-Assumptions!$C$24*Assumptions!$C$28))-Costs!$C$18)-Costs!$C$13 | I18: =G18*Assumptions!$C$6 | J18: =IFERROR(G18/((Capacity!$C$10*MIN(16,Assumptions!$C$9)*Assumptions!$C$23+Capacity!$C$11*MIN(Assumptions!$C$22,Assumptions!$C$10)*Assumptions!$C$23)*(B18*(1-Assumptions!$C$24*Assumptions!$C$28))),"n/a")
B19: 750000 | C19: =B19*Assumptions!$C$6 | D19: =C19/1800000 | E19: =IFERROR(Costs!$C$13/((B19*(1-Assumptions!$C$24*Assumptions!$C$28))-Costs!$C$18),"n/a") | F19: =(Capacity!$C$10*MIN(12,Assumptions!$C$9)*Assumptions!$C$23+Capacity!$C$11*MIN(Assumptions!$C$22,Assumptions!$C$10)*Assumptions!$C$23)*((B19*(1-Assumptions!$C$24*Assumptions!$C$28))-Costs!$C$18)-Costs!$C$13 | G19: =(Capacity!$C$10*MIN(16,Assumptions!$C$9)*Assumptions!$C$23+Capacity!$C$11*MIN(Assumptions!$C$22,Assumptions!$C$10)*Assumptions!$C$23)*((B19*(1-Assumptions!$C$24*Assumptions!$C$28))-Costs!$C$18)-Costs!$C$13 | H19: =(Capacity!$C$10*MIN(20,Assumptions!$C$9)*Assumptions!$C$23+Capacity!$C$11*MIN(Assumptions!$C$22,Assumptions!$C$10)*Assumptions!$C$23)*((B19*(1-Assumptions!$C$24*Assumptions!$C$28))-Costs!$C$18)-Costs!$C$13 | I19: =G19*Assumptions!$C$6 | J19: =IFERROR(G19/((Capacity!$C$10*MIN(16,Assumptions!$C$9)*Assumptions!$C$23+Capacity!$C$11*MIN(Assumptions!$C$22,Assumptions!$C$10)*Assumptions!$C$23)*(B19*(1-Assumptions!$C$24*Assumptions!$C$28))),"n/a")
... B21: 900000 | C21: =B21*Assumptions!$C$6 | D21: =C21/1800000 | E21: =IFERROR(Costs!$C$13/((B21*(1-Assumptions!$C$24*Assumptions!$C$28))-Costs!$C$18),"n/a") | F21: =(Capacity!$C$10*MIN(12,Assumptions!$C$9)*Assumptions!$C$23+Capacity!$C$11*MIN(Assumptions!$C$22,Assumptions!$C$10)*Assumptions!$C$23)*((B21*(1-Assumptions!$C$24*Assumptions!$C$28))-Costs!$C$18)-Costs!$C$13 | G21: =(Capacity!$C$10*MIN(16,Assumptions!$C$9)*Assumptions!$C$23+Capacity!$C$11*MIN(Assumptions!$C$22,Assumptions!$C$10)*Assumptions!$C$23)*((B21*(1-Assumptions!$C$24*Assumptions!$C$28))-Costs!$C$18)-Costs!$C$13 | H21: =(Capacity!$C$10*MIN(20,Assumptions!$C$9)*Assumptions!$C$23+Capacity!$C$11*MIN(Assumptions!$C$22,Assumptions!$C$10)*Assumptions!$C$23)*((B21*(1-Assumptions!$C$24*Assumptions!$C$28))-Costs!$C$18)-Costs!$C$13 | I21: =G21*Assumptions!$C$6 | J21: =IFERROR(G21/((Capacity!$C$10*MIN(16,Assumptions!$C$9)*Assumptions!$C$23+Capacity!$C$11*MIN(Assumptions!$C$22,Assumptions!$C$10)*Assumptions!$C$23)*(B21*(1-Assumptions!$C$24*Assumptions!$C$28))),"n/a")
B23: Column D anchors you to the only solid competitor price found: Eduzone charges 1,800,000₮/year for 2×/week group maths ЭЕШ prep. A '3.0×' means you are asking parents for three times what the nearest visible competitor asks. That is a defensible position only if the difference is visible to them every month — which is what the parent report is for (see Website sheet).
B25: Seats available: at cohort 12 / 16 / 20 the centre can enrol the number of students shown on the Capacity sheet. If break-even students exceeds seats available at your chosen price, that price cannot work at this capacity — raise price, raise utilisation, or cut fixed cost.

Sheet PnL
A1: P&L at the selected price
B2: Driven by the price on the Assumptions sheet. Change it there and this recalculates.
C4: Per month | D4: Per year
A5: REVENUE
B6: Students enrolled | C6: =Capacity!$C$14 | D6: =Capacity!$C$14 | E6: From Capacity.
B7: Effective tuition per student | C7: =Assumptions!$C$27*(1-Assumptions!$C$24*Assumptions!$C$28) | D7: =C7*Assumptions!$C$6 | E7: After blending the full-year discount across the mix.
B8: Tuition revenue | C8: =C6*C7 | D8: =C8*Assumptions!$C$6
B9: Registration / materials fee | C9: =Assumptions!$C$29*C6/Assumptions!$C$6 | D9: =Assumptions!$C$29*C6 | E9: One-off, spread across the year.
B10: TOTAL REVENUE | C10: =C8+C9 | D10: =D8+D9
A12: COSTS
B13: Hired teachers | C13: =-Costs!$C$5 | D13: =C13*Assumptions!$C$6
B14: Owner teaching time (costed) | C14: =-Costs!$C$6 | D14: =C14*Assumptions!$C$6 | E14: NOT free — see README.
B15: Admin | C15: =-Costs!$C$7 | D15: =C15*Assumptions!$C$6
B16: Rent + utilities | C16: =-(Costs!$C$8+Costs!$C$9) | D16: =C16*12 | E16: Rent runs 12 months even if you teach 10.
B17: Technology | C17: =-Costs!$C$10 | D17: =C17*12
B18: Marketing | C18: =-Costs!$C$11 | D18: =C18*12
B19: Other / contingency | C19: =-Costs!$C$12 | D19: =C19*12
B20: Materials + food (variable) | C20: =-Costs!$C$18*C6 | D20: =C20*Assumptions!$C$6
B21: TOTAL COST | C21: =SUM(C13:C20) | D21: =SUM(D13:D20)
A23: RESULT
B24: PROFIT | C24: =C10+C21 | D24: =D10+D21
B25: Margin | C25: =IFERROR(C24/C10,0) | D25: =IFERROR(D24/D10,0)
B26: Break-even students | C26: =IFERROR(Costs!$C$13/(C7-Costs!$C$18),"n/a") | D26: =C26 | E26: At this price.
B27: Seats of cushion above break-even | C27: =C6-C26 | D27: =C27 | E27: How many students you can lose before the centre loses money.
B29: Profit here is AFTER charging the owner's teaching time at the opportunity-cost rate. A small positive profit therefore still means the owner is being paid for teaching. A negative profit means the centre is not covering the owner's time on top of its bills.

Sheet Enrolment
A1: Full school year vs monthly subscription
B2: Same student, two contracts. The question is what churn costs you, and whether the full-year discount is cheaper than that churn.
A4: ONE STUDENT, ONE SCHOOL YEAR
C5: Full year | D5: Monthly | E5: Difference
B6: Headline price per month | C6: =Assumptions!$C$27 | D6: =Assumptions!$C$27 | E6: =C6-D6 | G6: Same list price.
B7: Less full-year discount | C7: =-Assumptions!$C$27*Assumptions!$C$28 | D7: =0 | E7: =C7-D7 | G7: Discount is the price of commitment.
B8: Net price per month | C8: =C6+C7 | D8: =D6+D7 | E8: =C8-D8
B9: Expected months paid | C9: =Assumptions!$C$6 | D9: =IFERROR((1-(1-Assumptions!$C$25)^Assumptions!$C$6)/Assumptions!$C$25,Assumptions!$C$6) | E9: =C9-D9 | G9: Monthly: expected months before churn, over a 10-month year. Full year: committed.
B10: Revenue per student per year | C10: =C8*C9 | D10: =D8*D9 | E10: =C10-D10
B11: Less cost to replace the leaver | C11: =0 | D11: =-Assumptions!$C$50*(1-(C9=D9))*Assumptions!$C$25*Assumptions!$C$6 | E11: =C11-D11 | G11: Marketing spend to refill an empty seat.
B12: Less lost margin on the empty seat | C12: =0 | D12: =-(C9-D9)*(D8-Costs!$C$18)*0.5 | E12: =C12-D12 | G12: A seat that empties mid-year is rarely refilled instantly. Assumes half the lost months are recovered.
B13: NET CONTRIBUTION PER STUDENT PER YEAR | C13: =C10+C11+C12 | D13: =D10+D11+D12 | E13: =C13-D13
B15: Is the full-year discount worth it? | C15: =IF(E13>0,"YES — commitment beats churn at these settings","NO — the discount costs more than the churn it prevents")
B16: The answer flips on two numbers only: the discount (Assumptions) and monthly churn (Assumptions). Find the churn rate at which they break even by changing churn until the difference above reaches zero.
A18: WHOLE CENTRE, AT THE SELECTED MIX
B19: Students on each plan | C19: =Capacity!$C$14*Assumptions!$C$24 | D19: =Capacity!$C$14*(1-Assumptions!$C$24) | E19: =C19-D19
B20: Net contribution per year | C20: =C19*C13 | D20: =D19*D13 | E20: =C20-D20
B22: Combined net contribution per year | C22: =C20+D20
B24: Practical note not in the arithmetic: a full-year contract in Mongolia is only as good as the family's ability to pay through February. Tsagaan Sar puts heavy pressure on household cash. A full-year commitment paid in 10 monthly instalments carries most of the retention benefit with far less payment risk than demanding the year upfront — and the CashFlow sheet shows why February is the month to worry about.

Sheet Website
A1: The website: bundled, add-on, and as its own product
A3: QUESTION 1 — BUNDLE IT INTO THE CENTRE FEE, OR SELL IT AS AN ADD-ON?
B4: The strategic argument for bundling is that the site is what makes the high fee legible: it produces the monthly evidence report. Modelled below with numbers, not opinion.
C6: Bundled | D6: Add-on | E6: Diff
B7: Centre students | C7: =Capacity!$C$14 | D7: =Capacity!$C$14 | E7: =C7-D7 | F7: Same roll either way.
B8: Tuition per student per month | C8: =Assumptions!$C$27*(1+Assumptions!$C$55) | D8: =Assumptions!$C$27 | E8: =C8-D8 | F8: Bundling supports a higher headline fee because the report justifies it.
B9: Add-on revenue per student per month | C9: =0 | D9: =Assumptions!$C$53*Assumptions!$C$54 | E9: =C9-D9 | F9: Add-on sold to a fraction of families only.
B10: Revenue per student per month | C10: =C8+C9 | D10: =D8+D9 | E10: =C10-D10
B11: Monthly churn | C11: =MAX(0,Assumptions!$C$25-Assumptions!$C$56) | D11: =Assumptions!$C$25 | E11: =C11-D11 | F11: Every family sees the report every month, so bundling also retains.
B12: Expected months paid | C12: =IFERROR((1-(1-C11)^Assumptions!$C$6)/C11,Assumptions!$C$6) | D12: =IFERROR((1-(1-D11)^Assumptions!$C$6)/D11,Assumptions!$C$6) | E12: =C12-D12
B13: Revenue per student per year | C13: =C10*C12 | D13: =D10*D12 | E13: =C13-D13
B14: CENTRE REVENUE PER YEAR | C14: =C13*C7 | D14: =D13*D7 | E14: =C14-D14
B16: Which wins, on these assumptions? | C16: =IF(E14>0,"BUNDLE","ADD-ON")
B17: This result is driven almost entirely by two yellow cells on Assumptions: the tuition uplift the bundle supports, and the churn reduction it delivers. Neither is observed — they are the hypotheses the first year should test. The break-even is: bundling wins whenever (uplift × tuition) exceeds (add-on price × attach rate), before even counting retention.
B19: There is also a non-financial argument the spreadsheet cannot hold: an add-on splits the parent body into those who can see the evidence and those who cannot. If the report is the proof of the premium, then charging separately for the proof undermines the premium.
A21: QUESTION 2 — WHAT IS THE VERIFIED-ATTEMPT ADVANTAGE WORTH?
B22: Mechanism (as described in the brief — doc 05 could not be read, see README): attempts made in the room are supervised. A human
B23: watched them happen. That makes the predicted ЭЕШ score trustworthy in a way no online-only competitor in Mongolia can match,
B24: because their data cannot distinguish a student's own work from a phone under the desk.
B26: Expressed to a parent, the product is not 'lessons'. It is: a defensible monthly answer to 'how is my child actually doing, and what
B27: happens if nothing changes?' — with the score projection, the topic-level gaps, and the evidence it rests on.
B29: Converting that into MNT — what a price premium is worth per year
B30: Premium over the visible competitor | C30: Annual fee/student | D30: Extra revenue/student/yr | E30: Centre extra revenue/yr
B31: At parity with Eduzone (1.0×) | C31: 1 | D31: =C31*1800000 | E31: =D31-1800000 | F31: =E31*Capacity!$C$14
B32: 1.5× the visible competitor | C32: 1.5 | D32: =C32*1800000 | E32: =D32-1800000 | F32: =E32*Capacity!$C$14
B33: 2.0× | C33: 2 | D33: =C33*1800000 | E33: =D33-1800000 | F33: =E33*Capacity!$C$14
B34: 2.5× | C34: 2.5 | D34: =C34*1800000 | E34: =D34-1800000 | F34: =E34*Capacity!$C$14
B35: 3.0× | C35: 3 | D35: =C35*1800000 | E35: =D35-1800000 | F35: =E35*Capacity!$C$14
B36: 4.0× | C36: 4 | D36: =C36*1800000 | E36: =D36-1800000 | F36: =E36*Capacity!$C$14
B38: Read this as: 'to justify charging 2.5× what Eduzone charges, the monthly report has to be worth about 2.7m₮ a year to a parent.' That is the sentence to test on ten real parents before launch. Note the anchor: UB families already pay 8–10m₮/year for private school, and ISU families pay $24–44k — so the ceiling on willingness to pay is set by perceived quality, not by the tutoring market.
A40: QUESTION 3 — THE PUBLIC WEBSITE AS ITS OWN PRODUCT
B41: Non-centre users. Twelve registered today, no monetisation. Modelled as a funnel.
B43: Registered users after 12 months | C43: =Assumptions!$C$58+Assumptions!$C$59*12 | E43: Growth is an assumption — no traffic data was supplied.
B44: Paying users at that point | C44: =C43*Assumptions!$C$60
B45: Monthly revenue | C45: =C44*Assumptions!$C$57
B46: Annual revenue (run rate) | C46: =C45*12
B47: …as a share of centre revenue | C47: =IFERROR(C46/PnL!$C$10/Assumptions!$C$6,0) | E47: Sense-check on where the effort should go.
B49: On any plausible assumption the public site is a rounding error next to the centre in year one. That is not an argument against building it — it is an argument for treating it as (a) the marketing funnel that fills the centre and (b) the delivery mechanism for the parent report, and NOT as a revenue line that deserves to compete for attention with filling classrooms.
B51: Suggested tier split — to be decided, not modelled
B52: FREE — practice questions, worked solutions, unverified self-scored progress. Enough to be genuinely useful and to rank in search.
...

Sheet CashFlow
A1: Cash-flow calendar — Aug 2026 to Aug 2027
B2: Against the Mongolian school year. Student numbers in blue are editable — they are a judgement, not an output.
C4: Aug-26 | D4: Sep-26 | E4: Oct-26 | F4: Nov-26 | G4: Dec-26 | H4: Jan-27 | I4: Feb-27 | J4: Mar-27 | K4: Apr-27 | L4: May-27 | M4: Jun-27 | N4: Jul-27 | O4: Aug-27
B5: Phase | C5: Setup | D5: Start | E5: Report | F5: Peak | G5: Peak | H5: Intake | I5: Tsagaan Sar | J5: Peak | K5: Peak | L5: Exam run | M5: ЭЕШ | N5: Summer | O5: Setup
B6: Students enrolled | C6: =ROUND(Capacity!$C$14*0,0) | D6: =ROUND(Capacity!$C$14*0.55,0) | E6: =ROUND(Capacity!$C$14*0.75,0) | F6: =ROUND(Capacity!$C$14*0.9,0) | G6: =ROUND(Capacity!$C$14*0.9,0) | H6: =ROUND(Capacity!$C$14*1.0,0) | I6: =ROUND(Capacity!$C$14*0.95,0) | J6: =ROUND(Capacity!$C$14*0.95,0) | K6: =ROUND(Capacity!$C$14*0.95,0) | L6: =ROUND(Capacity!$C$14*0.95,0) | M6: =ROUND(Capacity!$C$14*0.9,0) | N6: =ROUND(Capacity!$C$14*0.25,0) | O6: =ROUND(Capacity!$C$14*0.1,0)
B7: (as % of steady-state roll) | C7: 0 | D7: 0.55 | E7: 0.75 | F7: 0.9 | G7: 0.9 | H7: 1 | I7: 0.95 | J7: 0.95 | K7: 0.95 | L7: 0.95 | M7: 0.9 | N7: 0.25 | O7: 0.1
B9: Tuition revenue | C9: =C6*Assumptions!$C$27*(1-Assumptions!$C$24*Assumptions!$C$28)*0 | D9: =D6*Assumptions!$C$27*(1-Assumptions!$C$24*Assumptions!$C$28)*1 | E9: =E6*Assumptions!$C$27*(1-Assumptions!$C$24*Assumptions!$C$28)*1 | F9: =F6*Assumptions!$C$27*(1-Assumptions!$C$24*Assumptions!$C$28)*1 | G9: =G6*Assumptions!$C$27*(1-Assumptions!$C$24*Assumptions!$C$28)*1 | H9: =H6*Assumptions!$C$27*(1-Assumptions!$C$24*Assumptions!$C$28)*1 | I9: =I6*Assumptions!$C$27*(1-Assumptions!$C$24*Assumptions!$C$28)*1 | J9: =J6*Assumptions!$C$27*(1-Assumptions!$C$24*Assumptions!$C$28)*1 | K9: =K6*Assumptions!$C$27*(1-Assumptions!$C$24*Assumptions!$C$28)*1 | ... M9: =M6*Assumptions!$C$27*(1-Assumptions!$C$24*Assumptions!$C$28)*1 | N9: =N6*Assumptions!$C$27*(1-Assumptions!$C$24*Assumptions!$C$28)*0 | O9: =O6*Assumptions!$C$27*(1-Assumptions!$C$24*Assumptions!$C$28)*0
B10: Fixed costs | C10: =-(Costs!$C$7+Costs!$C$8+Costs!$C$9+Costs!$C$10+Costs!$C$11+Costs!$C$12)-Costs!$C$5*MAX(0,Assumptions!$C$51)-Costs!$C$6*0 | D10: =-(Costs!$C$7+Costs!$C$8+Costs!$C$9+Costs!$C$10+Costs!$C$11+Costs!$C$12)-Costs!$C$5*MAX(1,Assumptions!$C$51)-Costs!$C$6*1 | E10: =-(Costs!$C$7+Costs!$C$8+Costs!$C$9+Costs!$C$10+Costs!$C$11+Costs!$C$12)-Costs!$C$5*MAX(1,Assumptions!$C$51)-Costs!$C$6*1 | F10: =-(Costs!$C$7+Costs!$C$8+Costs!$C$9+Costs!$C$10+Costs!$C$11+Costs!$C$12)-Costs!$C$5*MAX(1,Assumptions!$C$51)-Costs!$C$6*1 | G10: =-(Costs!$C$7+Costs!$C$8+Costs!$C$9+Costs!$C$10+Costs!$C$11+Costs!$C$12)-Costs!$C$5*MAX(1,Assumptions!$C$51)-Costs!$C$6*1 | H10: =-(Costs!$C$7+Costs!$C$8+Costs!$C$9+Costs!$C$10+Costs!$C$11+Costs!$C$12)-Costs!$C$5*MAX(1,Assumptions!$C$51)-Costs!$C$6*1 | I10: =-(Costs!$C$7+Costs!$C$8+Costs!$C$9+Costs!$C$10+Costs!$C$11+Costs!$C$12)-Costs!$C$5*MAX(1,Assumptions!$C$51)-Costs!$C$6*1 | J10: =-(Costs!$C$7+Costs!$C$8+Costs!$C$9+Costs!$C$10+Costs!$C$11+Costs!$C$12)-Costs!$C$5*MAX(1,Assumptions!$C$51)-Costs!$C$6*1 | K10: =-(Costs!$C$7+Costs!$C$8+Costs!$C$9+Costs!$C$10+Costs!$C$11+Costs!$C$12)-Costs!$C$5*MAX(1,Assumptions!$C$51)-Costs!$C$6*1 | ... M10: =-(Costs!$C$7+Costs!$C$8+Costs!$C$9+Costs!$C$10+Costs!$C$11+Costs!$C$12)-Costs!$C$5*MAX(1,Assumptions!$C$51)-Costs!$C$6*1 | N10: =-(Costs!$C$7+Costs!$C$8+Costs!$C$9+Costs!$C$10+Costs!$C$11+Costs!$C$12)-Costs!$C$5*MAX(0,Assumptions!$C$51)-Costs!$C$6*0 | O10: =-(Costs!$C$7+Costs!$C$8+Costs!$C$9+Costs!$C$10+Costs!$C$11+Costs!$C$12)-Costs!$C$5*MAX(0,Assumptions!$C$51)-Costs!$C$6*0
B11: (owner time not charged in non-teaching months)
B12: Variable costs | C12: =-C6*Costs!$C$18*0 | D12: =-D6*Costs!$C$18*1 | E12: =-E6*Costs!$C$18*1 | F12: =-F6*Costs!$C$18*1 | G12: =-G6*Costs!$C$18*1 | H12: =-H6*Costs!$C$18*1 | I12: =-I6*Costs!$C$18*1 | J12: =-J6*Costs!$C$18*1 | K12: =-K6*Costs!$C$18*1 | ... M12: =-M6*Costs!$C$18*1 | N12: =-N6*Costs!$C$18*0 | O12: =-O6*Costs!$C$18*0
B13: One-off setup / launch marketing | C13: -4000000 | D13: -1000000 | E13: 0 | F13: 0 | G13: 0 | H13: -1000000 | I13: 0 | J13: 0 | K13: 0 | L13: 0 | M13: 0 | N13: 0 | O13: -3000000
B14: NET CASH | C14: =C9+C10+C12+C13 | D14: =D9+D10+D12+D13 | E14: =E9+E10+E12+E13 | F14: =F9+F10+F12+F13 | G14: =G9+G10+G12+G13 | H14: =H9+H10+H12+H13 | I14: =I9+I10+I12+I13 | J14: =J9+J10+J12+J13 | ... O14: =O9+O10+O12+O13
B15: CUMULATIVE CASH | C15: =C14 | D15: =C15+D14 | E15: =D15+E14 | F15: =E15+F14 | G15: =F15+G14 | H15: =G15+H14 | I15: =H15+I14 | J15: =I15+J14 | K15: =J15+K14 | ... O15: =N15+O14
A17: THE TIGHT MONTHS
B18: AUG 2026 — the worst month, and it is now. Fit-out, furniture, deposits and launch marketing all land before a single tugrik of tuition.
B19: Rent, utilities and any hired teacher's salary start before the first lesson. This is the month that needs cash in the bank, not a forecast.
B21: FEB 2027 — Tsagaan Sar. Household cash goes to family obligations; tuition is exactly the kind of payment that slips. Expect late payment
B22: rather than cancellation, but model it: this is the month a monthly-subscription roll quietly shrinks. (Confirm the 2027 dates.)
B24: JUL–AUG 2027 — the post-exam cliff. ЭЕШ is sat in late June; the graduating cohort leaves at once and does not come back. Fixed costs —
B25: rent above all — continue through a near-zero revenue summer, straight into next year's setup spend. Two consecutive drains.
B27: The structural point: this business collects revenue over ten months and pays rent over twelve. A summer intensive, or a deliberate
B28: cash reserve carried out of the spring, is not optional — it is what makes September possible.

Sheet Scenarios
A1: Scenarios
B2: Three coherent pictures. Edit the blue inputs in each column. Costs come from the Costs sheet in every case.
C4: Conservative | D4: Base | E4: Stretch
B5: Tuition ₮/student/month | C5: 350000 | D5: 450000 | E5: 650000 | F5: The lever you are choosing.
B6: Cohort size | C6: 12 | D6: 16 | E6: 20 | F6: Bigger cohorts earn more but dilute the premium.
B7: Seat fill rate | C7: 0.65 | D7: 0.85 | E7: 0.95
B8: Slot utilisation | C8: 0.45 | D8: 0.55 | E8: 0.7
B10: Students | C10: =ROUND(((((Assumptions!$C$14*Assumptions!$C$15)+(Assumptions!$C$16*Assumptions!$C$17))*C8)/Assumptions!$C$19)*MIN(C6,Assumptions!$C$9)*C7+((((Assumptions!$C$14*Assumptions!$C$15)+(Assumptions!$C$16*Assumptions!$C$17))*C8)/Assumptions!$C$19)*MIN(Assumptions!$C$22,Assumptions!$C$10)*C7*Assumptions!$C$11,0) | D10: =ROUND(((((Assumptions!$C$14*Assumptions!$C$15)+(Assumptions!$C$16*Assumptions!$C$17))*D8)/Assumptions!$C$19)*MIN(D6,Assumptions!$C$9)*D7+((((Assumptions!$C$14*Assumptions!$C$15)+(Assumptions!$C$16*Assumptions!$C$17))*D8)/Assumptions!$C$19)*MIN(Assumptions!$C$22,Assumptions!$C$10)*D7*Assumptions!$C$11,0) | E10: =ROUND(((((Assumptions!$C$14*Assumptions!$C$15)+(Assumptions!$C$16*Assumptions!$C$17))*E8)/Assumptions!$C$19)*MIN(E6,Assumptions!$C$9)*E7+((((Assumptions!$C$14*Assumptions!$C$15)+(Assumptions!$C$16*Assumptions!$C$17))*E8)/Assumptions!$C$19)*MIN(Assumptions!$C$22,Assumptions!$C$10)*E7*Assumptions!$C$11,0)
B11: Contact hours/week | C11: =(((Assumptions!$C$14*Assumptions!$C$15)+(Assumptions!$C$16*Assumptions!$C$17))*C8)*(1+Assumptions!$C$11)*Assumptions!$C$13 | D11: =(((Assumptions!$C$14*Assumptions!$C$15)+(Assumptions!$C$16*Assumptions!$C$17))*D8)*(1+Assumptions!$C$11)*Assumptions!$C$13 | E11: =(((Assumptions!$C$14*Assumptions!$C$15)+(Assumptions!$C$16*Assumptions!$C$17))*E8)*(1+Assumptions!$C$11)*Assumptions!$C$13
B12: Hired teachers required | C12: =ROUNDUP(MAX(0,(((Assumptions!$C$14*Assumptions!$C$15)+(Assumptions!$C$16*Assumptions!$C$17))*C8)*(1+Assumptions!$C$11)*Assumptions!$C$13-Assumptions!$C$34)/Assumptions!$C$32,0) | D12: =ROUNDUP(MAX(0,(((Assumptions!$C$14*Assumptions!$C$15)+(Assumptions!$C$16*Assumptions!$C$17))*D8)*(1+Assumptions!$C$11)*Assumptions!$C$13-Assumptions!$C$34)/Assumptions!$C$32,0) | E12: =ROUNDUP(MAX(0,(((Assumptions!$C$14*Assumptions!$C$15)+(Assumptions!$C$16*Assumptions!$C$17))*E8)*(1+Assumptions!$C$11)*Assumptions!$C$13-Assumptions!$C$34)/Assumptions!$C$32,0)
B13: Fixed cost / month | C13: =C12*Assumptions!$C$31*(1+Assumptions!$C$33)+Assumptions!$C$34*Assumptions!$C$7*Assumptions!$C$35+Assumptions!$C$37*Assumptions!$C$36*(1+Assumptions!$C$33)+Assumptions!$C$39+Assumptions!$C$40+Assumptions!$C$41+(Assumptions!$C$46+Assumptions!$C$47)*Assumptions!$C$5+Assumptions!$C$48+Assumptions!$C$49 | D13: =D12*Assumptions!$C$31*(1+Assumptions!$C$33)+Assumptions!$C$34*Assumptions!$C$7*Assumptions!$C$35+Assumptions!$C$37*Assumptions!$C$36*(1+Assumptions!$C$33)+Assumptions!$C$39+Assumptions!$C$40+Assumptions!$C$41+(Assumptions!$C$46+Assumptions!$C$47)*Assumptions!$C$5+Assumptions!$C$48+Assumptions!$C$49 | E13: =E12*Assumptions!$C$31*(1+Assumptions!$C$33)+Assumptions!$C$34*Assumptions!$C$7*Assumptions!$C$35+Assumptions!$C$37*Assumptions!$C$36*(1+Assumptions!$C$33)+Assumptions!$C$39+Assumptions!$C$40+Assumptions!$C$41+(Assumptions!$C$46+Assumptions!$C$47)*Assumptions!$C$5+Assumptions!$C$48+Assumptions!$C$49 | F13: Same cost logic as the Costs sheet, recomputed per scenario.
B14: Revenue / month | C14: =C10*C5*(1-Assumptions!$C$24*Assumptions!$C$28) | D14: =D10*D5*(1-Assumptions!$C$24*Assumptions!$C$28) | E14: =E10*E5*(1-Assumptions!$C$24*Assumptions!$C$28)
B15: Variable cost / month | C15: =C10*Costs!$C$18 | D15: =D10*Costs!$C$18 | E15: =E10*Costs!$C$18
B16: PROFIT / MONTH | C16: =C14-C15-C13 | D16: =D14-D15-D13 | E16: =E14-E15-E13
B17: PROFIT / YEAR | C17: =C16*Assumptions!$C$6 | D17: =D16*Assumptions!$C$6 | E17: =E16*Assumptions!$C$6 | F17: After paying the owner for teaching. Rent in the two non-teaching months is not deducted here — see CashFlow.
B18: Break-even students | C18: =IFERROR(C13/(C5*(1-Assumptions!$C$24*Assumptions!$C$28)-Costs!$C$18),"n/a") | D18: =IFERROR(D13/(D5*(1-Assumptions!$C$24*Assumptions!$C$28)-Costs!$C$18),"n/a") | E18: =IFERROR(E13/(E5*(1-Assumptions!$C$24*Assumptions!$C$28)-Costs!$C$18),"n/a")
B19: Cushion (students above break-even) | C19: =C10-C18 | D19: =D10-D18 | E19: =E10-E18 | F19: Negative means this scenario loses money.
B20: Annual fee vs Eduzone (1.8m₮) | C20: =C5*Assumptions!$C$6/1800000 | D20: =D5*Assumptions!$C$6/1800000 | E20: =E5*Assumptions!$C$6/1800000 | F20: How big an ask this is, against the only clearly published competitor price.
B21: Students in building, parallel session | C21: =MIN(C6,Assumptions!$C$9)+MIN(Assumptions!$C$22,Assumptions!$C$10)*Assumptions!$C$11 | D21: =MIN(D6,Assumptions!$C$9)+MIN(Assumptions!$C$22,Assumptions!$C$10)*Assumptions!$C$11 | E21: =MIN(E6,Assumptions!$C$9)+MIN(Assumptions!$C$22,Assumptions!$C$10)*Assumptions!$C$11
B22: Within the stated ~20 capacity? | C22: =IF(C21<=Assumptions!$C$12,"OK","OVER") | D22: =IF(D21<=Assumptions!$C$12,"OK","OVER") | E22: =IF(E21<=Assumptions!$C$12,"OK","OVER") | F22: Physical check on the flat, scenario by scenario.
B23: Physical ceiling on the roll (100% fill) | C23: =(((Assumptions!$C$14*Assumptions!$C$15)+(Assumptions!$C$16*Assumptions!$C$17))*C8*(Assumptions!$C$9+Assumptions!$C$10*Assumptions!$C$11))/Assumptions!$C$19 | D23: =(((Assumptions!$C$14*Assumptions!$C$15)+(Assumptions!$C$16*Assumptions!$C$17))*D8*(Assumptions!$C$9+Assumptions!$C$10*Assumptions!$C$11))/Assumptions!$C$19 | E23: =(((Assumptions!$C$14*Assumptions!$C$15)+(Assumptions!$C$16*Assumptions!$C$17))*E8*(Assumptions!$C$9+Assumptions!$C$10*Assumptions!$C$11))/Assumptions!$C$19 | F23: The roll above must sit below this or the timetable does not exist.
B25: Note what the Conservative column is really testing: it is not 'a bad year', it is 'the premium did not land'. Lower price, smaller cohorts, emptier seats. If that column survives, the downside is bounded. If it does not, the plan depends on the premium working first time — which is a different kind of risk and worth knowing before September.
B27: TREAT STRETCH WITH SUSPICION. It compounds a high price, the largest cohort, near-full seats AND high utilisation at the same time. Each is individually possible; all four together, in year one, in a converted flat, is not a plan — it is a coincidence. The Base column is the one to argue about.
